# Understanding JavaScript Promises: An Explanatory Guide

## Introduction: What are Promises? (The Restaurant Analogy)

Imagine you're at a restaurant:

1.  **You place an order (initiating an asynchronous operation):** You ask for a burger. You don't get it instantly. This is like calling a JavaScript function that does something that takes time (e.g., fetching data from a server, reading a file).
2.  **You get a receipt or a buzzer (the Promise object):** This isn't the burger itself, but it's a *promise* from the restaurant that they *will* give you a burger (or tell you if they're out of burgers). This receipt/buzzer is the Promise object in JavaScript. It represents the *future* outcome.
3.  **The Promise has states:**
      * **Pending:** Your buzzer hasn't gone off yet. The kitchen is working on it. Your Promise is "pending" â€“ the operation isn't complete yet.
      * **Fulfilled (Resolved):** Your buzzer goes off\! Your burger is ready\! The Promise is "fulfilled." You get your data (the burger).
      * **Rejected:** The waiter comes back and says, "Sorry, we're out of patties." The Promise is "rejected." An error occurred.
4.  **What you do next (`.then()`, `.catch()`, `.finally()`):**
      * **`.then(handleSuccess)`:** When the buzzer goes off (Promise is fulfilled), you go get your burger. The `.then()` method takes a function that will be called with the result when the Promise is successful.
      * **`.catch(handleFailure)`:** If there's no burger (Promise is rejected), you decide what to do instead. The `.catch()` method takes a function that will be called with the error if the Promise fails.
      * **`.finally(doThisAnyway)`:** Regardless, you'll eventually leave the restaurant. The `.finally()` method executes code after the promise is settled, whether it was fulfilled or rejected.

Promises help manage asynchronous operations gracefully, avoiding complex nested callbacks (often called "callback hell") and making asynchronous code easier to read and maintain.

-----

## Detailed Examples from the Guide

Here are the 15 examples from the article, explained with analogies and their expected outputs:

-----

**Example 1: Basic Promise Creation**

  * **Analogy:** Ordering a custom-made T-shirt online.
      * You place the order (`new Promise`).
      * The company (the executor function) works on it (`setTimeout`).
      * They'll either tell you "It's ready and shipped\!" (`resolve`) or "Sorry, we're out of your size." (`reject`).
      * You're waiting to hear back to either track your package (`.then`) or look for another T-shirt (`.catch`).
  * **Code Snippet:**
    ```javascript
    // ===== 1. BASIC PROMISE CREATION =====
    const basicPromise = new Promise((resolve, reject) => {
        // Simulate an async operation
        setTimeout(() => {
            const randomNumber = Math.random();
            if (randomNumber > 0.5) {
                resolve(`Success! Random number: ${randomNumber}`);
            } else {
                reject(`Failed! Random number: ${randomNumber}`);
            }
        }, 1000);
    });

    // Using the promise
    basicPromise
        .then(result => console.log("1. Basic Promise Success:", result))
        .catch(error => console.log("1. Basic Promise Error:", error));
    ```
  * **Expected Output (Example - actual number will vary due to `Math.random()`):**
      * **If `randomNumber` \> 0.5 (e.g., 0.712...):**
        ```
        1. Basic Promise Success: Success! Random number: 0.712...
        ```
      * **If `randomNumber` \<= 0.5 (e.g., 0.345...):**
        ```
        1. Basic Promise Error: Failed! Random number: 0.345...
        ```
    *(Note: Only one of these lines will appear, after a 1-second delay.)*

  * **What it does:** This code defines a `basicPromise`. Inside this promise, a `setTimeout` function is used to simulate a task that takes 1 second (1000 milliseconds) to complete. After 1 second, it generates a random number.
      * If the number is greater than 0.5, the promise is **resolved** (succeeds) with a success message including the number.
      * If the number is 0.5 or less, the promise is **rejected** (fails) with a failure message including the number.
  * **`.then(result => ...)`:** This part says: "IF the `basicPromise` resolves successfully, THEN execute this function with the success message (`result`)."
  * **`.catch(error => ...)`:** This part says: "IF the `basicPromise` is rejected, THEN execute this function with the failure message (`error`)."
  * **Concept Illustrated:** The fundamental structure of creating a Promise with an executor function that calls `resolve` on success or `reject` on failure. It also shows how to consume the promise's outcome using `.then()` and `.catch()`.


-----

**Example 2: Promise States**

  * **Analogy:** Tracking a package delivery.
      * **Pending:** You've ordered, but the tracking site just says "In Transit." (`pendingPromise`)
      * **Fulfilled:** Tracking updates to "Delivered\!" (`Promise.resolve()`)
      * **Rejected:** Tracking updates to "Delivery Attempt Failed - Package Damaged." (`Promise.reject()`)
  * **Code Snippet:**
    ```javascript
    // ===== 2. PROMISE STATES =====
    console.log("\n=== Promise States ===");

    // Pending Promise
    const pendingPromise = new Promise((resolve) => {
        // Never resolves, stays pending
    });
    console.log("2. Pending Promise state:", pendingPromise);

    // Fulfilled Promise
    const fulfilledPromise = Promise.resolve("Fulfilled value");
    console.log("2. Fulfilled Promise state:", fulfilledPromise);

    // Rejected Promise
    const rejectedPromise = Promise.reject("Rejection reason");
    console.log("2. Rejected Promise state:", rejectedPromise);

    // Catching the rejection to prevent unhandled promise rejection
    rejectedPromise.catch(reason => console.log("2. Caught rejection:", reason));
    ```
  * **Expected Output:**
    ```
    
    === Promise States ===
    2. Pending Promise state: Promise { <pending> }
    2. Fulfilled Promise state: Promise { 'Fulfilled value' }
    2. Rejected Promise state: Promise { <rejected> 'Rejection reason' }
    2. Caught rejection: Rejection reason
    ```
    *(Note: The exact string representation of promises might vary slightly between JavaScript environments.)*

  * **What it does:**
      * `pendingPromise`: Creates a promise that is never resolved or rejected. When you log it, you'll see its state is "pending."
      * `fulfilledPromise`: Uses `Promise.resolve("Fulfilled value")` which is a shorthand to create a promise that is *already* fulfilled with the given value. Logging it shows its state as "fulfilled."
      * `rejectedPromise`: Uses `Promise.reject("Rejection reason")` which creates a promise that is *already* rejected with the given reason. Logging it shows its state as "rejected."
      * The `.catch()` on `rejectedPromise` is important. If you don't handle a rejected promise, Node.js or browsers often log an "unhandled promise rejection" error, which is bad practice.
  * **Concept Illustrated:** The three states of a Promise:
    1.  **Pending:** The initial state; the operation has not completed yet.
    2.  **Fulfilled:** The operation completed successfully.
    3.  **Rejected:** The operation failed.
        It also shows shortcuts `Promise.resolve()` and `Promise.reject()` for creating promises that are immediately settled.


-----

**Example 3: Chaining Promises**

  * **Analogy:** A treasure hunt with multiple clues.
    1.  `WorkspaceUser(1)`: Find the first clue (user data). This takes some time.
    2.  `.then(user => fetchPosts(user.id))`: The first clue tells you where to look for the second clue (user's posts). Finding the second clue is also a task that takes time.
    3.  `.then(posts => posts.length)`: The second clue (the posts) tells you a number (how many posts there are). This is a quick calculation.
    4.  `.then(count => ...)`: You use that number.
  * **Code Snippet:**
    ```javascript
    // ===== 3. CHAINING PROMISES =====
    function fetchUser(id) {
        return new Promise((resolve) => {
            setTimeout(() => {
                resolve({ id, name: `User${id}`, email: `user${id}@example.com` });
            }, 500);
        });
    }

    function fetchPosts(userId) {
        return new Promise((resolve) => {
            setTimeout(() => {
                resolve([
                    { id: 1, title: `Post 1 by User ${userId}` },
                    { id: 2, title: `Post 2 by User ${userId}` }
                ]);
            }, 300);
        });
    }

    console.log("\n=== Promise Chaining ===");
    fetchUser(1)
        .then(user => {
            console.log("3. User fetched:", user);
            return fetchPosts(user.id); // Return a new Promise
        })
        .then(posts => {
            console.log("3. Posts fetched:", posts);
            return posts.length; // Return a value
        })
        .then(count => {
            console.log("3. Number of posts:", count);
        })
        .catch(error => {
            console.log("3. Error in chain:", error);
        });
    ```
  * **Expected Output:**
    ```
    
    === Promise Chaining ===
    (after ~0.5s)
    3. User fetched: { id: 1, name: 'User1', email: 'user1@example.com' }
    (after ~0.3s more)
    3. Posts fetched: [
      { id: 1, title: 'Post 1 by User 1' },
      { id: 2, title: 'Post 2 by User 1' }
    ]
    (immediately after previous)
    3. Number of posts: 2
    ```

  * **What it does:**
    1.  `WorkspaceUser(1)` is called. It returns a promise that resolves after 500ms with a user object.
    2.  The first `.then(user => ...)` receives this `user` object. It logs the user and then calls `WorkspacePosts(user.id)`. Critically, `WorkspacePosts` also returns a promise.
    3.  Because the first `.then()` returns a promise (`WorkspacePosts(...)`), the *next* `.then()` waits for *that new promise* to resolve.
    4.  The second `.then(posts => ...)` receives the `posts` array (resolved from `WorkspacePosts`). It logs the posts and returns `posts.length` (a number).
    5.  Because the second `.then()` returns a simple value (the count), that value is immediately passed to the third `.then()`.
    6.  The third `.then(count => ...)` receives the `count` and logs it.
    7.  If any of the promises in this chain were to reject (e.g., if `WorkspaceUser` had a `reject()` call), the chain would skip subsequent `.then()` blocks and go directly to the `.catch()`.
  * **Concept Illustrated:** How to perform a sequence of asynchronous operations. Each `.then()` can receive data from the previous step and can either pass a simple value to the next step or return a new promise, making the chain wait for that new promise. This avoids "callback hell."


-----

**Example 4: Error Handling in Promises**

  * **Analogy:** A multi-stage rocket launch.
    1.  `unreliableOperation()`: Stage 1 ignition. It might succeed or fail.
    2.  First `.then()`: If Stage 1 is okay, ground control performs a check. But during this check, they *simulate* an anomaly (`throw new Error`).
    3.  Second `.then()`: This is Stage 2 ignition. It's skipped because of the anomaly.
    4.  `.catch()`: Mission control's emergency procedure. It handles the anomaly and reports "Recovered from error." The mission can proceed in a limited capacity.
    5.  Third `.then()`: A recovery task is performed with the "Recovered from error" message.
    6.  `.finally()`: The launch tower safety checks are performed regardless of mission success or partial recovery.
  * **Code Snippet:**
    ```javascript
    // ===== 4. ERROR HANDLING IN PROMISES =====
    console.log("\n=== Error Handling ===");

    function unreliableOperation() {
        return new Promise((resolve, reject) => {
            setTimeout(() => {
                if (Math.random() > 0.7) {
                    resolve("Operation succeeded");
                } else {
                    reject(new Error("Operation failed"));
                }
            }, 500);
        });
    }

    unreliableOperation()
        .then(result => {
            console.log("4. Success:", result);
            throw new Error("Throwing from then");
        })
        .then(result => {
            console.log("4. This won't execute");
        })
        .catch(error => {
            console.log("4. Caught error:", error.message);
            return "Recovered from error"; // Can recover from errors
        })
        .then(result => {
            console.log("4. After error recovery:", result);
        })
        .finally(() => {
            console.log("4. Finally block always executes");
        });
    ```
  * **Expected Output (if `unreliableOperation` resolves initially, then error is thrown):**
    ```
    
    === Error Handling ===
    (after ~0.5s)
    4. Success: Operation succeeded
    (immediately after previous)
    4. Caught error: Throwing from then
    (immediately after previous)
    4. After error recovery: Recovered from error
    (immediately after previous)
    4. Finally block always executes
    ```
  * **Expected Output (if `unreliableOperation` rejects initially):**
    ```
    
    === Error Handling ===
    (after ~0.5s)
    4. Caught error: Operation failed
    (immediately after previous)
    4. After error recovery: Recovered from error
    (immediately after previous)
    4. Finally block always executes
    ```

  * **What it does:**
    1.  `unreliableOperation()` returns a promise that might resolve or reject.
    2.  **First `.then()`:** If `unreliableOperation` resolves, this `.then()` logs the success. Then, importantly, it `throw new Error("Throwing from then")`. Throwing an error inside a `.then()` or `.catch()` will cause the promise chain to enter a rejected state.
    3.  **Second `.then()`:** This block is skipped because the previous `.then()` threw an error (making the promise chain rejected).
    4.  **`.catch()`:** This block *catches* the error thrown from the first `.then()`. It logs the error message. Then, it `return "Recovered from error"`. When a `.catch()` returns a non-Error value, it "recovers" the promise chain, meaning the chain transitions back to a fulfilled state with this returned value.
    5.  **Third `.then()`:** Because the `.catch()` recovered the chain, this `.then()` executes and receives "Recovered from error" as its `result`.
    6.  **`.finally()`:** This block executes regardless of whether the promise chain resolved or rejected at the end. It's used for cleanup tasks.
  * **Concept Illustrated:**
      * Errors (rejections or thrown errors in `.then()`) propagate down the chain to the nearest `.catch()`.
      * A `.catch()` can "handle" an error and optionally "recover" the chain by returning a value.
      * `.finally()` is for code that must run regardless of the outcome.


-----

**Example 5: `Promise.all()`**

  * **Analogy:** Assembling a group for a trip. You need everyone (`promise1`, `promise2`, `promise3`) to confirm they are ready *before* the trip can start.
      * If everyone confirms (`.then(values => ...)`), you get a list of all confirmations. The list is in the order you asked them, not necessarily the order they replied.
      * If even one person cancels (`failingPromise`), the whole trip is called off for now (`.catch(error => ...)`).
  * **Code Snippet:**
    ```javascript
    // ===== 5. PROMISE.ALL() =====
    console.log("\n=== Promise.all() ===");

    const promise1 = Promise.resolve(3);
    const promise2 = new Promise(resolve => setTimeout(() => resolve('foo'), 1000));
    const promise3 = Promise.resolve(42);

    Promise.all([promise1, promise2, promise3])
        .then(values => {
            console.log("5. Promise.all() results:", values);
        })
        .catch(error => {
            console.log("5. Promise.all() error:", error);
        });

    // Example with one rejection
    const failingPromise = Promise.reject("One failed");
    Promise.all([promise1, failingPromise, promise3])
        .then(values => {
            console.log("5. This won't execute");
        })
        .catch(error => {
            console.log("5. Promise.all() with failure:", error);
        });
    ```
  * **Expected Output:**
    ```
    
    === Promise.all() ===
    (after ~1s, due to promise2)
    5. Promise.all() results: [ 3, 'foo', 42 ]
    (immediately, for the second Promise.all call)
    5. Promise.all() with failure: One failed
    ```

  * **What it does:**
      * **First `Promise.all()`:**
          * It's given an array of three promises: `promise1` (resolves immediately to 3), `promise2` (resolves to 'foo' after 1 second), `promise3` (resolves immediately to 42).
          * `Promise.all()` waits for *all* these promises to resolve.
          * Once all are resolved, its `.then(values => ...)` callback is executed. The `values` variable will be an array containing the resolved values of the input promises, *in the same order as they were in the input array*: `[3, 'foo', 42]`.
      * **Second `Promise.all()`:**
          * It's given an array that includes `failingPromise` (which is immediately rejected).
          * Because one of the promises rejects, `Promise.all()` as a whole immediately rejects.
          * The `.then()` block is skipped, and the `.catch(error => ...)` is executed with the reason from `failingPromise` ("One failed").
  * **Concept Illustrated:** `Promise.all()` is used when you have multiple asynchronous operations and you need to wait for all of them to complete successfully before proceeding. If any one of them fails, `Promise.all()` itself fails.

-----

**Example 6: `Promise.allSettled()`**

  * **Analogy:** Checking the status of multiple homework assignments after submission. You want to know the outcome of each one (Graded: A, Graded: C, Missing), even if some are not yet graded or have issues. You're not waiting for *all* to be A's to know their individual statuses.
  * **Code Snippet:**
    ```javascript
    // ===== 6. PROMISE.ALLSETTLED() =====
    console.log("\n=== Promise.allSettled() ===");

    const mixedPromises = [
        Promise.resolve('Success 1'),
        Promise.reject('Error 1'),
        Promise.resolve('Success 2'),
        Promise.reject('Error 2')
    ];

    Promise.allSettled(mixedPromises)
        .then(results => {
            console.log("6. Promise.allSettled() results:");
            results.forEach((result, index) => {
                if (result.status === 'fulfilled') {
                    console.log(`   ${index}: Fulfilled with ${result.value}`);
                } else {
                    console.log(`   ${index}: Rejected with ${result.reason}`);
                }
            });
        });
    ```
  * **Expected Output:**
    ```
    
    === Promise.allSettled() ===
    6. Promise.allSettled() results:
       0: Fulfilled with Success 1
       1: Rejected with Error 1
       2: Fulfilled with Success 2
       3: Rejected with Error 2
    ```

  * **What it does:**
      * `mixedPromises` is an array containing promises that will resolve and promises that will reject.
      * `Promise.allSettled()` takes this array. Unlike `Promise.all()`, it does *not* reject if one of the promises rejects. Instead, it waits for *all* promises to "settle" (i.e., either become fulfilled or rejected).
      * The `.then(results => ...)` callback is always executed (unless there's an error in how `allSettled` itself is called, which is rare).
      * The `results` variable is an array of objects. Each object describes the outcome of the corresponding promise from the input array:
          * If a promise was fulfilled: `{ status: 'fulfilled', value: <resolved_value> }`
          * If a promise was rejected: `{ status: 'rejected', reason: <rejection_reason> }`
      * The code then iterates through `results` and logs the outcome of each individual promise.
  * **Concept Illustrated:** `Promise.allSettled()` is useful when you want to run multiple asynchronous operations and need to know the outcome of each one, regardless of whether some succeeded and some failed. You want to process all results, not just stop at the first failure.


-----

**Example 7: `Promise.race()`**

  * **Analogy:** Three delivery drivers (`fastPromise`, `slowPromise`, `mediumPromise`) are sent out. You only care about the first one who returns, and what they bring (or if they report a problem upon arrival).
      * First race: `fastPromise` returns first with their package.
      * Second race: `quickReject` returns first, but reports a problem (`rejects`).
  * **Code Snippet:**
    ```javascript
    // ===== 7. PROMISE.RACE() =====
    console.log("\n=== Promise.race() ===");

    const fastPromise = new Promise(resolve => setTimeout(() => resolve('Fast'), 500));
    const slowPromise = new Promise(resolve => setTimeout(() => resolve('Slow'), 1500));
    const mediumPromise = new Promise(resolve => setTimeout(() => resolve('Medium'), 1000));

    Promise.race([fastPromise, slowPromise, mediumPromise])
        .then(result => {
            console.log("7. Promise.race() winner:", result);
        });

    // Race with rejection
    const quickReject = new Promise((_, reject) => setTimeout(() => reject('Quick Error'), 300));
    Promise.race([quickReject, slowPromise])
        .then(result => {
            console.log("7. This won't execute");
        })
        .catch(error => {
            console.log("7. Promise.race() error:", error);
        });
    ```
  * **Expected Output:**
    ```
    
    === Promise.race() ===
    (after ~0.3s for the second race)
    7. Promise.race() error: Quick Error
    (after ~0.5s for the first race)
    7. Promise.race() winner: Fast
    ```
    *(Note: The order of these two blocks appearing in the console depends on which `Promise.race` is initiated first if they were in the same block, but here they are separate. The `quickReject` race will log its result first as its timeout is shorter.)*

  * **What it does:**
      * **First `Promise.race()`:**
          * It's given an array of three promises: `fastPromise` (resolves in 500ms), `slowPromise` (resolves in 1500ms), and `mediumPromise` (resolves in 1000ms).
          * `Promise.race()` waits for the *first* promise in the array to settle (either fulfill or reject).
          * In this case, `fastPromise` settles first by resolving to 'Fast'.
          * So, `Promise.race()` resolves with 'Fast', and the `.then()` logs this. The other promises (`slowPromise`, `mediumPromise`) continue to run, but their results are ignored by this `Promise.race()`.
      * **Second `Promise.race()`:**
          * It's given `quickReject` (rejects in 300ms) and `slowPromise` (resolves in 1500ms).
          * `quickReject` settles first by rejecting with 'Quick Error'.
          * So, `Promise.race()` rejects with 'Quick Error', and the `.catch()` logs this.
  * **Concept Illustrated:** `Promise.race()` is used when you have multiple asynchronous operations and you only care about the result of the first one that finishes. This can be used for things like implementing timeouts (racing an operation against a timer promise that rejects).

-----

**Example 8: `async/await` with Promises**

  * **Analogy:** Following a cooking recipe step-by-step, where some steps involve waiting (e.g., "marinate for 30 minutes").
      * `async function fetchUserData`: This is the entire recipe.
      * `const user = await fetchUser(userId)`: "Step 1: Prepare the user data. `await` until it's fully prepared before moving to Step 2." (like waiting for marination).
      * `const posts = await fetchPosts(user.id)`: "Step 2: Based on Step 1, get the posts. `await` until they are all gathered."
      * `try...catch`: If you mess up a step (e.g., burn the sauce), you handle the error (start over or make a different dish) instead of the whole cooking process halting abruptly.
  * **Code Snippet:** (uses `WorkspaceUser` and `WorkspacePosts` from Example 3)
    ```javascript
    // ===== 8. ASYNC/AWAIT WITH PROMISES =====
    console.log("\n=== Async/Await ===");

    async function fetchUserData(userId) {
        try {
            console.log("8. Starting to fetch user data...");
            const user = await fetchUser(userId);
            console.log("8. User fetched:", user);

            const posts = await fetchPosts(user.id);
            console.log("8. Posts fetched:", posts);

            return { user, posts };
        } catch (error) {
            console.log("8. Error in fetchUserData:", error);
            throw error;
        }
    }

    fetchUserData(2)
        .then(result => {
            console.log("8. Complete user data:", result);
        })
        .catch(error => {
            console.log("8. Final error:", error);
        });
    ```
  * **Expected Output:**
    ```
    
    === Async/Await ===
    8. Starting to fetch user data...
    (after ~0.5s for fetchUser)
    8. User fetched: { id: 2, name: 'User2', email: 'user2@example.com' }
    (after ~0.3s more for fetchPosts)
    8. Posts fetched: [
      { id: 1, title: 'Post 1 by User 2' },
      { id: 2, title: 'Post 2 by User 2' }
    ]
    (immediately after previous)
    8. Complete user data: {
      user: { id: 2, name: 'User2', email: 'user2@example.com' },
      posts: [
        { id: 1, title: 'Post 1 by User 2' },
        { id: 2, title: 'Post 2 by User 2' }
      ]
    }
    ```

  * **What it does:**
      * `async function fetchUserData(userId)`: The `async` keyword before `function` means this function will automatically return a Promise.
      * `const user = await fetchUser(userId);`:
          * `await` can *only* be used inside an `async` function.
          * It tells JavaScript to *pause* the execution of `WorkspaceUserData` at this line until the promise returned by `WorkspaceUser(userId)` settles.
          * If `WorkspaceUser(userId)` resolves, its resolved value (the user object) is assigned to the `user` variable, and the function continues.
          * If `WorkspaceUser(userId)` rejects, the `await` expression throws that rejection as an error, which can be caught by the `try...catch` block.
      * The same logic applies to `const posts = await fetchPosts(user.id);`.
      * `return { user, posts };`: If all awaited promises resolve successfully, this return value becomes the resolved value of the promise that `WorkspaceUserData` itself returns.
      * `try...catch` block: This is the standard JavaScript way to handle errors. In an `async` function, it can catch errors thrown by `await` (which are rejections from the awaited promises).
      * When `WorkspaceUserData(2)` is called, it returns a promise. We then use `.then()` and `.catch()` to handle its final outcome, just like any other promise.
  * **Concept Illustrated:** `async/await` provides a more synchronous-looking syntax for writing asynchronous code that involves promises. It makes promise chains easier to read and write, especially for sequential operations, and allows using standard `try...catch` for error handling.

-----

**Example 9: Parallel Async Operations**

  * **Analogy:** Three people need to fetch a different ingredient from a grocery store.
      * **`sequentialExecution`:** Person 1 goes, gets ingredient A, returns. Then Person 2 goes, gets ingredient B, returns. Then Person 3 goes, gets ingredient C, returns. Total time is sum of individual trips.
      * **`parallelExecution`:** All three people go to the store *at the same time* to get their respective ingredients. They all return. Total time is the time taken by the slowest person.
  * **Code Snippet:** (uses `WorkspaceUser` from Example 3, which takes \~500ms)
    ```javascript
    // ===== 9. PARALLEL ASYNC OPERATIONS =====
    console.log("\n=== Parallel Async Operations ===");

    // Sequential execution (slower)
    async function sequentialExecution() {
        console.log("9. Sequential execution starting...");
        const start = Date.now();
        const user1 = await fetchUser(1);
        const user2 = await fetchUser(2);
        const user3 = await fetchUser(3);
        const elapsed = Date.now() - start;
        console.log(`9. Sequential took ${elapsed}ms`);
        return [user1, user2, user3];
    }

    // Parallel execution (faster)
    async function parallelExecution() {
        console.log("9. Parallel execution starting...");
        const start = Date.now();
        const promises = [
            fetchUser(1),
            fetchUser(2),
            fetchUser(3)
        ];
        const users = await Promise.all(promises);
        const elapsed = Date.now() - start;
        console.log(`9. Parallel took ${elapsed}ms`);
        return users;
    }

    // Compare execution times
    parallelExecution().then(users => console.log("9. Parallel results:", users.map(u=>u.id)));
    // sequentialExecution().then(users => console.log("9. Sequential results:", users.map(u=>u.id)));
    ```
  * **Expected Output (if `parallelExecution` is run, `sequentialExecution` is commented out):**
    ```
    
    === Parallel Async Operations ===
    9. Parallel execution starting...
    (after ~500-550ms, actual time may vary slightly)
    9. Parallel took <approx_500_to_550>ms
    9. Parallel results: [ 1, 2, 3 ]
    ```
  * **Expected Output (if `sequentialExecution` is run, `parallelExecution` is commented out):**
    ```
    
    === Parallel Async Operations ===
    9. Sequential execution starting...
    (after ~1500-1550ms, actual time may vary slightly)
    9. Sequential took <approx_1500_to_1550>ms
    9. Sequential results: [ 1, 2, 3 ]
    ```
  * **What it does:**
      * **`sequentialExecution()`:**
          * It uses `await` for each `WorkspaceUser` call one after the other.
          * `await fetchUser(1)`: The function pauses for \~500ms.
          * Then `await fetchUser(2)`: The function pauses for another \~500ms.
          * Then `await fetchUser(3)`: The function pauses for another \~500ms.
          * Total time is roughly the sum of individual durations (e.g., 500 + 500 + 500 = \~1500ms).
      * **`parallelExecution()`:**
          * It calls `WorkspaceUser(1)`, `WorkspaceUser(2)`, and `WorkspaceUser(3)` *without* `await` in front of them immediately. This means all three `WorkspaceUser` operations start at roughly the same time and run concurrently (in parallel).
          * `WorkspaceUser()` returns a promise, so `promises` becomes an array of three pending promises.
          * `const users = await Promise.all(promises);`: The `await` here pauses the function until *all* promises in the `promises` array have resolved.
          * Total time is roughly the duration of the *slowest single* `WorkspaceUser` call (e.g., \~500ms, assuming they all take about the same time).
  * **Concept Illustrated:** When you have multiple independent asynchronous operations, running them in parallel using `Promise.all()` is much more efficient than running them sequentially using multiple `await` statements one after another.


-----

**Example 10: Promise Timeouts**

  * **Analogy:** A timed pop quiz. You have a task (`slowOperation`) to complete (answer the questions), but there's also a timer (`timeout` promise). If the timer goes off before you submit your answers, you've "timed out."
  * **Code Snippet:**
    ```javascript
    // ===== 10. PROMISE TIMEOUTS =====
    console.log("\n=== Promise Timeouts ===");

    function withTimeout(promise, milliseconds) {
        const timeout = new Promise((_, reject) => {
            setTimeout(() => reject(new Error(`Timeout after ${milliseconds}ms`)), milliseconds);
        });
        return Promise.race([promise, timeout]);
    }

    const slowOperation = new Promise(resolve => {
        setTimeout(() => resolve("Finally done!"), 2000); // Takes 2 seconds
    });

    withTimeout(slowOperation, 1500) // Timeout is 1.5 seconds
        .then(result => console.log("10. Operation completed:", result))
        .catch(error => console.log("10. Operation timed out:", error.message));
    ```
  * **Expected Output:**
    ```
    
    === Promise Timeouts ===
    (after 1.5s)
    10. Operation timed out: Timeout after 1500ms
    ```
    *(This is because `slowOperation` takes 2000ms, but the timeout is set to 1500ms. The timeout promise rejects first.)*

  * **What it does:**
      * The `withTimeout` function takes an existing `promise` and a `milliseconds` duration.
      * Inside `withTimeout`, it creates a new `timeout` promise. This `timeout` promise is designed to *reject* with a timeout error after the specified `milliseconds`.
      * It then uses `Promise.race([promise, timeout])`. This means it will wait for either the original `promise` to settle OR the `timeout` promise to settle, whichever happens first.
      * In the example, `slowOperation` is set to resolve after 2000ms (2 seconds).
      * `withTimeout(slowOperation, 1500)` is called, setting a timeout of 1500ms (1.5 seconds).
      * Since 1.5 seconds is less than 2 seconds, the `timeout` promise will reject *before* `slowOperation` resolves.
      * Therefore, `Promise.race()` will adopt the outcome of the `timeout` promise (rejection), and the `.catch()` block will be executed, logging the timeout error.
  * **Concept Illustrated:** A common pattern for implementing timeouts for promise-based operations. You "race" your operation against a promise that rejects after a certain duration.


-----

**Example 11: Promise Factories and Lazy Evaluation**

  * **Analogy:**
      * **Eager Promise (`eagerPromise`):** Pre-ordering a limited-edition video game the moment it's announced. The process (reserving your copy, potential payment processing) starts immediately.
      * **Promise Factory (`createPromise`):** Having a function `orderGame()` written down. The game is only actually ordered (and the process starts) when you *call* `orderGame()`. You can call it multiple times for multiple orders.
  * **Code Snippet:**
    ```javascript
    // ===== 11. PROMISE FACTORIES AND LAZY EVALUATION =====
    console.log("\n=== Promise Factories ===");

    const eagerPromise = new Promise(resolve => {
        console.log("11. Eager Promise started!");
        setTimeout(() => resolve("Eager result"), 1000);
    });

    function createPromise() {
        return new Promise(resolve => {
            console.log("11. Lazy Promise started!");
            setTimeout(() => resolve("Lazy result"), 1000);
        });
    }

    console.log("11. Created promises");

    setTimeout(() => {
        console.log("11. Using eager promise...");
        eagerPromise.then(result => console.log("11.", result));
    }, 2000);

    setTimeout(() => {
        console.log("11. Creating and using lazy promise...");
        createPromise().then(result => console.log("11.", result));
    }, 3000);
    ```
  * **Expected Output (order is crucial):**
    ```
    
    === Promise Factories ===
    11. Eager Promise started!
    11. Created promises
    (After 2 seconds total from script start; eager promise resolved 1s ago)
    11. Using eager promise...
    11. Eager result
    (After 3 seconds total from script start)
    11. Creating and using lazy promise...
    11. Lazy Promise started!
    (After 4 seconds total from script start; lazy promise resolves 1s after being started)
    11. Lazy result
    ```

  * **What it does:**
      * **`eagerPromise`:** The moment `const eagerPromise = new Promise(...)` is executed, the code inside the promise executor function (the `console.log` and `setTimeout`) starts running. The "Eager Promise started\!" message is logged immediately, and its internal timer begins.
      * **`createPromise()` (Promise Factory):** This is a function. The code inside *its* promise executor doesn't run until `createPromise()` is actually *called*.
      * **Execution Flow:**
        1.  "Eager Promise started\!" logs.
        2.  "11. Created promises..." logs.
        3.  After 2 seconds: "11. Using eager promise..." logs. The `eagerPromise` would have already resolved by now (after 1 second from its creation), so its `.then()` executes and logs "11. Eager result".
        4.  After 3 seconds: "11. Creating and using lazy promise..." logs. NOW `createPromise()` is called, so "11. Lazy Promise started\!" logs, and its internal timer starts. One second *after this point*, its `.then()` will execute and log "11. Lazy result".
  * **Concept Illustrated:**
      * **Eager Evaluation:** A promise defined directly (`new Promise(...)`) starts its asynchronous operation immediately upon definition.
      * **Lazy Evaluation (Promise Factory):** Wrapping promise creation in a function (a factory) means the asynchronous operation only starts when you call that function. This gives you more control over when the operation begins, allows for retries with fresh promises, and can be more memory-efficient if the operation isn't always needed.

-----

**Example 12: Promise Chaining with Branching**

  * **Analogy:** Planning a weekend activity based on the weather forecast.
    1.  `Promise.resolve(data)`: Your initial plan (e.g., `data` = how many people are joining).
    2.  First `.then()`: You confirm the number of people (`data * 2` - maybe a misinterpretation in analogy, let's say this is a prep step like "check supplies").
    3.  Second `.then()` (The Branching Point - Weather Check):
          * If `doubled > 10` (Good weather predicted): You decide on an "Outdoor Picnic" (add 100 to some score).
          * Else (Bad weather predicted): You decide on an "Indoor Movie Marathon" (add 1 to the score).
    4.  Final `.then()`: You look at the "fun score" of your chosen activity.
  * **Code Snippet:**
    ```javascript
    // ===== 12. PROMISE CHAINING WITH BRANCHING =====
    console.log("\n=== Promise Branching ===");

    function processData(data) {
        return Promise.resolve(data)
            .then(data => {
                console.log("12. Processing:", data);
                return data * 2;
            })
            .then(doubled => {
                if (doubled > 10) {
                    return Promise.resolve(doubled).then(val => {
                        console.log("12. Large value branch:", val);
                        return val + 100;
                    });
                } else {
                    return Promise.resolve(doubled).then(val => {
                        console.log("12. Small value branch:", val);
                        return val + 1;
                    });
                }
            })
            .then(result => {
                console.log("12. Final result:", result);
                return result;
            });
    }

    processData(3);  // Small value branch
    processData(8);  // Large value branch
    ```
  * **Expected Output:**
    ```
    
    === Promise Branching ===
    12. Processing: 3
    12. Small value branch: 6
    12. Final result: 7
    12. Processing: 8
    12. Large value branch: 16
    12. Final result: 116
    ```


  * **What it does:**
      * The `processData` function takes some `data`.
      * The first `.then()` doubles the `data`.
      * The second `.then()` receives this `doubled` value and has an `if/else` condition:
          * If `doubled > 10`, it executes one block of code (large value branch) which logs a message and returns a promise that resolves to `val + 100`.
          * Else, it executes another block of code (small value branch) which logs a message and returns a promise that resolves to `val + 1`.
      * Crucially, *both branches return a promise* (or a value that gets wrapped in a promise).
      * The final `.then(result => ...)` receives the resolved value from whichever branch was taken.
  * **Concept Illustrated:** How to introduce conditional logic within a promise chain. Based on a condition, you can execute different asynchronous (or synchronous) steps, and the chain will continue with the result of the chosen branch. Both conditional paths should eventually lead to a settled promise for the subsequent `.then()` to work consistently.


-----

**Example 13: Promise Retry Mechanism**

  * **Analogy:** Trying to connect to a spotty Wi-Fi network.
      * `unstableOperation`: Each attempt to connect. It might succeed, or it might fail.
      * `retry(operation, maxAttempts, delay)`: You'll try connecting (`operation`) up to `maxAttempts` times. If it fails, you'll wait a bit (`delay`) before trying again (hoping the signal improves).
      * If it connects, great\! If you run out of attempts, you give up and report "No Wi-Fi" (`throw new Error`).
  * **Code Snippet:**
    ```javascript
    // ===== 13. PROMISE RETRY MECHANISM =====
    console.log("\n=== Promise Retry Mechanism ===");

    function unstableOperation() {
        return new Promise((resolve, reject) => {
            if (Math.random() > 0.7) { // ~30% chance of success
                resolve("Success!");
            } else {
                reject(new Error("Random failure"));
            }
        });
    }

    async function retry(operation, maxAttempts, delay = 1000) {
        let lastError;
        for (let attempt = 1; attempt <= maxAttempts; attempt++) {
            try {
                console.log(`13. Attempt ${attempt}/${maxAttempts}`);
                const result = await operation();
                console.log(`13. Succeeded on attempt ${attempt}`);
                return result;
            } catch (error) {
                lastError = error;
                console.log(`13. Attempt ${attempt} failed:`, error.message);
                if (attempt < maxAttempts) {
                    console.log(`13. Waiting ${delay}ms before retry...`);
                    await new Promise(resolve => setTimeout(resolve, delay));
                }
            }
        }
        throw new Error(`All ${maxAttempts} attempts failed. Last error: ${lastError.message}`);
    }

    retry(unstableOperation, 3, 500)
        .then(result => console.log("13. Final success:", result))
        .catch(error => console.log("13. Final failure:", error.message));
    ```
  * **Expected Output (will vary due to `Math.random()`. This is one possible scenario where it succeeds on the 2nd attempt):**
    ```
    
    === Promise Retry Mechanism ===
    13. Attempt 1/3
    13. Attempt 1 failed: Random failure
    13. Waiting 500ms before retry...
    (after 500ms delay)
    13. Attempt 2/3
    13. Succeeded on attempt 2
    13. Final success: Success!
    ```
      * **Another possible scenario (fails all 3 times):**
        ```
        
        === Promise Retry Mechanism ===
        13. Attempt 1/3
        13. Attempt 1 failed: Random failure
        13. Waiting 500ms before retry...
        (after 500ms delay)
        13. Attempt 2/3
        13. Attempt 2 failed: Random failure
        13. Waiting 500ms before retry...
        (after 500ms delay)
        13. Attempt 3/3
        13. Attempt 3 failed: Random failure
        13. Final failure: All 3 attempts failed. Last error: Random failure
        ```

  * **What it does:**
      * `unstableOperation()` is a function that returns a promise. This promise has a chance of either resolving or rejecting.
      * The `retry` function is an `async` function designed to attempt a given `operation` (which should be a function that returns a promise, like `unstableOperation`) up to `maxAttempts` times.
      * Inside the `for` loop:
          * It `await operation()`. If this succeeds, the `result` is returned, and the `retry` function's promise resolves.
          * If `operation()` rejects, the `catch` block is executed. It logs the failure.
          * If it's not the last attempt, it waits for `delay` milliseconds (using `await new Promise(resolve => setTimeout(resolve, delay))`) before the next iteration of the loop.
      * If the loop finishes without the `operation` succeeding in any attempt, the `retry` function throws an error indicating that all attempts failed.
  * **Concept Illustrated:** A common pattern for handling operations that might fail intermittently (e.g., network requests). It demonstrates how to use `async/await` with a loop and delays to repeatedly try an asynchronous operation. The `operation` is passed as a function (a promise factory) so that a *new* attempt (a new promise) is made each time.

-----

**Example 14: Promise-based Event Emitter**

  * **Analogy:** Subscribing to a specific YouTube channel's notification bell for new video uploads.
      * `emitter.once('data')`: You click the bell for the 'data' channel. You now have a "subscription promise" that you'll be notified.
      * Multiple people can click the bell for the same 'data' channel.
      * `emitter.emit('data', { message: "New video!" })`: The 'data' channel uploads a new video. Everyone who clicked the bell gets a notification (their "subscription promise" resolves with the video info). Because it's `once`, after this notification, they'd have to click the bell again for future videos (though this emitter clears all listeners for that event).
  * **Code Snippet:**
    ```javascript
    // ===== 14. PROMISE-BASED EVENT EMITTER =====
    console.log("\n=== Promise-based Event Emitter ===");

    class PromiseEventEmitter {
        constructor() {
            this.listeners = {};
        }
        once(event) {
            return new Promise(resolve => {
                if (!this.listeners[event]) {
                    this.listeners[event] = [];
                }
                this.listeners[event].push(resolve);
            });
        }
        emit(event, data) {
            if (this.listeners[event]) {
                this.listeners[event].forEach(resolve => resolve(data));
                this.listeners[event] = [];
            }
        }
    }

    const emitter = new PromiseEventEmitter();

    emitter.once('data').then(data => console.log("14. Listener 1 received:", data));
    emitter.once('data').then(data => console.log("14. Listener 2 received:", data));

    setTimeout(() => {
        console.log("14. Emitting event...");
        emitter.emit('data', { message: "Hello from event!" });
    }, 1000);
    ```
  * **Expected Output:**
    ```
    
    === Promise-based Event Emitter ===
    (After 1 second)
    14. Emitting event...
    14. Listener 1 received: { message: 'Hello from event!' }
    14. Listener 2 received: { message: 'Hello from event!' }
    ```

  * **What it does:**
      * `PromiseEventEmitter` is a class that mimics a simple event emitter but uses promises.
      * `once(event)`: When you call this method (e.g., `emitter.once('data')`), it doesn't take a callback directly. Instead, it creates and returns a *new Promise*. The `resolve` function of this new promise is stored internally, associated with the `event` name. The idea is that this promise will resolve when the specified `event` is emitted.
      * `emit(event, data)`: When this method is called, it looks up all the stored `resolve` functions for the given `event`. It then calls each of these `resolve` functions, passing the `data` to them. This causes all the promises returned by previous calls to `once(event)` for that specific event to become fulfilled.
      * In the example:
        1.  Two calls to `emitter.once('data')` are made. Each returns a promise, and their respective `.then()` callbacks are set up, waiting for these promises to resolve.
        2.  After 1 second, `emitter.emit('data', ...)` is called.
        3.  This triggers the stored `resolve` functions for both promises, causing both `.then()` callbacks to execute with the emitted data.
  * **Concept Illustrated:** How promises can be used to manage events or signals. Instead of passing a callback to an event listener, you get a promise that resolves when the event occurs. This allows you to integrate event-driven patterns more cleanly with promise-based asynchronous flows (e.g., using `await emitter.once('data')` inside an `async` function).


-----

**Example 15: Promise Memory Management**

  * **Analogy:** A researcher using a library's special collections.
      * **`createLeakyPromise` (Conceptual leak):** The researcher requests a huge, rare manuscript (`bigData`). They only need one sentence from it. If, after finding that sentence, their request record (`Promise` closure) somehow keeps the *entire manuscript* marked as "in use by this researcher" indefinitely, even if the researcher only noted down the one sentence, that manuscript can't be properly archived or used by others. This is worse if a global list (`promiseStore`) keeps track of all manuscripts "in use" and never clears old entries.
      * **`createCleanPromise`:** The researcher requests the manuscript. They find the sentence, copy *only that sentence* (`result = bigData.length`, or just the specific piece of data). They then clearly signal they are done with the original manuscript. The manuscript can now be returned to the archives. The promise resolves with only the small, necessary piece of information.
  * **Code Snippet:**
    ```javascript
    // ===== 15. PROMISE MEMORY MANAGEMENT =====
    console.log("\n=== Promise Memory Management ===");

    let promiseStore = []; // Example of external store if used improperly

    function createLeakyPromise() {
        return new Promise(resolve => {
            const bigData = new Array(100000).fill('data');
            setTimeout(() => resolve('done'), 1000);
            // The article's comment "promiseStore.push(bigData);" shows an explicit leak.
            // The subtle promise leak is if the closure for 'resolve' keeps 'bigData' alive
            // longer than necessary if 'resolve' itself used 'bigData'.
        });
    }

    function createCleanPromise() {
        return new Promise(resolve => {
            const bigData = new Array(100000).fill('data');
            setTimeout(() => {
                const result = bigData.length; // Extract only needed data
                resolve(result);
                // bigData can be garbage collected now if not referenced elsewhere
            }, 1000);
        });
    }

    createCleanPromise().then(result => console.log("15. Clean promise result:", result));
    ```
  * **Expected Output:**
    ```
    
    === Promise Memory Management ===
    (after 1s)
    15. Clean promise result: 100000
    ```
    *(Note: Memory leaks are not typically visible in simple console output but are observed through performance monitoring tools over time and many operations.)*


  * **What it does (and what it's trying to show):**
      * **`createLeakyPromise()`:**
          * It creates a `bigData` array within the scope of the promise's executor function.
          * The comment `promiseStore.push(bigData); // Don't do this!` is slightly misplaced in the original code if it intends to show the promise itself causing a leak by closure. If `bigData` is pushed to an *external, persistent* array like `promiseStore` and `promiseStore` is never cleared, then `bigData` will indeed leak, regardless of the promise.
          * The more subtle point is that the closure created by the `resolve` function (even if `bigData` isn't explicitly passed *to* `resolve`) can keep `bigData` alive as long as the promise is pending or if the promise object itself is held onto and the JavaScript engine can't optimize away the reference. Once resolved, if the promise result doesn't include `bigData` and the promise object itself isn't unnecessarily kept, `bigData` *should* be collectible. The key is that anything referenced within the promise executor's scope *could* be kept alive if the promise (or its resolve/reject functions) maintains a reference to it.
      * **`createCleanPromise()`:**
          * It also creates `bigData`.
          * However, when it resolves, it resolves with `bigData.length`, which is just a number. It doesn't resolve with `bigData` itself.
          * After the `setTimeout` callback finishes, and assuming no other references to `bigData` exist, `bigData` becomes eligible for garbage collection because it's no longer reachable from the promise's result or its internal state once settled (assuming the engine is efficient). Setting `bigData = null;` is an explicit way to help break the reference.
  * **Concept Illustrated:**
      * Promises, like any closures in JavaScript, can inadvertently keep large objects in memory if those objects are part of the closure's scope and are still referenced (or potentially referenced) by the promise's internal workings or its result.


-----

**Bonus: Promise Execution Order (Microtasks vs. Macrotasks)**

The "Bonus: Promise Execution Order" section in the article explains a more advanced but crucial concept:

  * **Analogy:** A busy office with two types of to-do lists.

    1.  **Main Work (Synchronous Code):** The primary tasks you do immediately one after another.
    2.  **Urgent Short Tasks (Microtask Queue - Promises):** Quick, high-priority tasks that need to be done as soon as the current main task is finished, before anything else. (`Promise.resolve().then(...)`)
    3.  **Regular Tasks (Macrotask Queue - `setTimeout`, I/O):** Standard tasks that are scheduled and picked up one by one when the "Urgent Short Tasks" list is empty. (`setTimeout(...)`)

    The office worker (JavaScript event loop) will:

    1.  Finish all current "Main Work."
    2.  Check the "Urgent Short Tasks" list. If there are any, do ALL of them until the list is empty.
    3.  Only then, pick ONE "Regular Task" from that list.
    4.  After completing that one "Regular Task", go back to step 2 (check "Urgent Short Tasks" again, because the "Regular Task" might have added new urgent ones).

  * **Code Snippet (from original article):**

    ```javascript
    // ===== BONUS: PROMISE EXECUTION ORDER =====
    console.log("\n=== Promise Execution Order ===");

    console.log("1. Synchronous");                          // Sync

    setTimeout(() => console.log("2. setTimeout"), 0);      // Macrotask

    Promise.resolve().then(() => console.log("3. Promise.resolve")); // Microtask

    Promise.resolve().then(() => {                          // Microtask
        console.log("4. First Promise");
        return Promise.resolve();                           // Creates another microtask
    }).then(() => console.log("5. Chained Promise"));       // This is the new microtask

    console.log("6. End of script");                        // Sync
    ```

  * **Expected Output:**

    ```
    
    === Promise Execution Order ===
    1. Synchronous
    6. End of script
    3. Promise.resolve
    4. First Promise
    5. Chained Promise
    2. setTimeout
    ```

  * **What it does (and what it's trying to show):**
      * **`createLeakyPromise()`:**
          * It creates a `bigData` array within the scope of the promise's executor function.
          * The comment `promiseStore.push(bigData); // Don't do this!` is slightly misplaced in the original code if it intends to show the promise itself causing a leak by closure. If `bigData` is pushed to an *external, persistent* array like `promiseStore` and `promiseStore` is never cleared, then `bigData` will indeed leak, regardless of the promise.
          * The more subtle point is that the closure created by the `resolve` function (even if `bigData` isn't explicitly passed *to* `resolve`) can keep `bigData` alive as long as the promise is pending or if the promise object itself is held onto and the JavaScript engine can't optimize away the reference. Once resolved, if the promise result doesn't include `bigData` and the promise object itself isn't unnecessarily kept, `bigData` *should* be collectible. The key is that anything referenced within the promise executor's scope *could* be kept alive if the promise (or its resolve/reject functions) maintains a reference to it.
      * **`createCleanPromise()`:**
          * It also creates `bigData`.
          * However, when it resolves, it resolves with `bigData.length`, which is just a number. It doesn't resolve with `bigData` itself.
          * After the `setTimeout` callback finishes, and assuming no other references to `bigData` exist, `bigData` becomes eligible for garbage collection because it's no longer reachable from the promise's result or its internal state once settled (assuming the engine is efficient). Setting `bigData = null;` is an explicit way to help break the reference.
  * **Concept Illustrated:**
      * Promises, like any closures in JavaScript, can inadvertently keep large objects in memory if those objects are part of the closure's scope and are still referenced (or potentially referenced) by the promise's internal workings or its result.